<?xml version="1.0"?>
<robot xmlns:xacro="http://ros.org/wiki/xacro">
	<xacro:include filename="$(find staubli)/urdf/rx60l_macro.xacro"/>

	<xacro:macro name="staubli_rx60l_gripper" params="prefix">
		<!-- instantiate rx60l macro -->
		<!-- tool0 link unused by gripper -->
		<xacro:staubli_rx60l prefix="${prefix}" />

		<!-- gripper definition -->
		<joint name="${prefix}left_gripper_joint" type="revolute">
			<axis xyz="0 0 1"/>
			<limit effort="1000.0" lower="0.0" upper="0.548" velocity="0.5"/>
			<origin rpy="0 -1.570796327 0" xyz="0 0.01 0.008"/>
			<parent link="${prefix}staubli_rx60l_link7"/>
			<child link="${prefix}left_gripper"/>
		</joint>
		<link name="${prefix}left_gripper">
			<visual>
				<origin rpy="0.0 0 0" xyz="0 0 0"/>
				<geometry>
					<mesh filename="package://pr2_description/meshes/gripper_v0/l_finger.dae"/>
				</geometry>
			</visual>
		</link>
		<joint name="${prefix}left_tip_joint" type="fixed">
			<parent link="${prefix}left_gripper"/>
			<child link="${prefix}left_tip"/>
		</joint>
		<link name="${prefix}left_tip">
			<visual>
				<origin rpy="0.0 0 0" xyz="0.09137 0.00495 0"/>
				<geometry>
					<mesh filename="package://pr2_description/meshes/gripper_v0/l_finger_tip.dae"/>
				</geometry>
			</visual>
		</link>
		<joint name="${prefix}right_gripper_joint" type="revolute">
			<axis xyz="0 0 -1"/>
			<limit effort="1000.0" lower="0.0" upper="0.548" velocity="0.5"/>
			<origin rpy="0 -1.570796327 0" xyz="0 -0.01 0.008"/>
			<parent link="${prefix}staubli_rx60l_link7"/>
			<child link="${prefix}right_gripper"/>
		</joint>
		<link name="${prefix}right_gripper">
			<visual>
				<origin rpy="-3.1415 0 0" xyz="0 0 0"/>
				<geometry>
					<mesh filename="package://pr2_description/meshes/gripper_v0/l_finger.dae"/>
				</geometry>
			</visual>
		</link>
		<joint name="right_tip_joint" type="fixed">
			<parent link="${prefix}right_gripper"/>
			<child link="${prefix}right_tip"/>
		</joint>
		<link name="${prefix}right_tip">
			<visual>
				<origin rpy="-3.1415 0 0" xyz="0.09137 0.00495 0"/>
				<geometry>
					<mesh filename="package://pr2_description/meshes/gripper_v0/l_finger_tip.dae"/>
				</geometry>
			</visual>
		</link>

	</xacro:macro>
</robot>
