<?xml version="1.0" ?>
<!-- =================================================================================== -->
<!-- |    This document was autogenerated by xacro from rx60l_gripper.xacro            | -->
<!-- |    EDITING THIS FILE BY HAND IS NOT RECOMMENDED                                 | -->
<!-- =================================================================================== -->
<robot name="staubli_rx60l_gripper" xmlns:xacro="http://ros.org/wiki/xacro">
  <link name="staubli_rx60l_link1">
    <visual>
      <origin rpy="0 0 0" xyz="0 0 0"/>
      <geometry>
        <mesh filename="package://staubli/meshes/rx60l/visual/rx60bl_hb.dae" scale="0.001 0.001 0.001"/>
      </geometry>
      <material name="Yellow">
        <color rgba="245 196 0 1.0"/>
      </material>
    </visual>
    <collision>
      <origin rpy="0 0 0" xyz="0 0 0"/>
      <geometry>
        <mesh filename="package://staubli/meshes/rx60l/collision/rx60bl_hb.stl" scale="0.001 0.001 0.001"/>
      </geometry>
      <material name="Blue">
        <color rgba="0 0 255 1.0"/>
      </material>
    </collision>
  </link>
  <link name="staubli_rx60l_link2">
    <visual>
      <origin rpy="0 0 0" xyz="0 0 0"/>
      <geometry>
        <mesh filename="package://staubli/meshes/rx60l/visual/rx60bl_hb1.dae" scale="0.001 0.001 0.001"/>
      </geometry>
      <material name="Yellow">
        <color rgba="245 196 0 1.0"/>
      </material>
    </visual>
    <collision>
      <origin rpy="0 0 0" xyz="0 0 0"/>
      <geometry>
        <mesh filename="package://staubli/meshes/rx60l/visual/rx60bl_hb1.dae" scale="0.001 0.001 0.001"/>
      </geometry>
      <material name="Green">
        <color rgba="0 0 255 1.0"/>
      </material>
    </collision>
  </link>
  <link name="staubli_rx60l_link3">
    <visual>
      <origin rpy="0 0 0" xyz="0 0 0"/>
      <geometry>
        <mesh filename="package://staubli/meshes/rx60l/visual/rx60bl_hb2.stl" scale="0.001 0.001 0.001"/>
      </geometry>
      <material name="White">
        <color rgba="0 0 255 1.0"/>
      </material>
    </visual>
    <collision>
      <origin rpy="0 0 0" xyz="0 0 0"/>
      <geometry>
        <mesh filename="package://staubli/meshes/rx60l/visual/rx60bl_hb2.stl" scale="0.001 0.001 0.001"/>
      </geometry>
      <material name="Blue">
        <color rgba="0 0 255 1.0"/>
      </material>
    </collision>
  </link>
  <link name="staubli_rx60l_link4">
    <visual>
      <origin rpy="0 0 0" xyz="0 0 0"/>
      <geometry>
        <mesh filename="package://staubli/meshes/rx60l/visual/rx60bl_hb3.dae" scale="0.001 0.001 0.001"/>
      </geometry>
      <material name="Red">
        <color rgba="0 0 255 1.0"/>
      </material>
    </visual>
    <collision>
      <origin rpy="0 0 0" xyz="0 0 0"/>
      <geometry>
        <mesh filename="package://staubli/meshes/rx60l/visual/rx60bl_hb3.dae" scale="0.001 0.001 0.001"/>
      </geometry>
      <material name="Blue">
        <color rgba="0 0 255 1.0"/>
      </material>
    </collision>
  </link>
  <link name="staubli_rx60l_link5">
    <visual>
      <origin rpy="0 0 0" xyz="0 0 0"/>
      <geometry>
        <mesh filename="package://staubli/meshes/rx60l/visual/rx60bl_hb4.dae" scale="0.001 0.001 0.001"/>
      </geometry>
      <material name="Blue">
        <color rgba="0 0 255 1.0"/>
      </material>
    </visual>
    <collision>
      <origin rpy="0 0 0" xyz="0 0 0"/>
      <geometry>
        <mesh filename="package://staubli/meshes/rx60l/visual/rx60bl_hb4.dae" scale="0.001 0.001 0.001"/>
      </geometry>
      <material name="Blue">
        <color rgba="0 0 255 1.0"/>
      </material>
    </collision>
  </link>
  <link name="staubli_rx60l_link6">
    <visual>
      <origin rpy="0 0 0" xyz="0 0 0"/>
      <geometry>
        <mesh filename="package://staubli/meshes/rx60l/visual/rx60bl_hb5.dae" scale="0.001 0.001 0.001"/>
      </geometry>
      <material name="Blue">
        <color rgba="0 0 255 1.0"/>
      </material>
    </visual>
    <collision>
      <origin rpy="0 0 0" xyz="0 0 0"/>
      <geometry>
        <mesh filename="package://staubli/meshes/rx60l/visual/rx60bl_hb5.dae" scale="0.001 0.001 0.001"/>
      </geometry>
      <material name="Blue">
        <color rgba="0 0 255 1.0"/>
      </material>
    </collision>
  </link>
  <link name="staubli_rx60l_link7">
    <visual>
      <origin rpy="0 0 0" xyz="0 0 0"/>
      <geometry>
        <mesh filename="package://staubli/meshes/rx60l/visual/rx60bl_hb6.dae" scale="0.001 0.001 0.001"/>
      </geometry>
      <material name="Gray">
        <color rgba="100 100 100 1.0"/>
      </material>
    </visual>
    <collision>
      <origin rpy="0 0 0" xyz="0 0 0"/>
      <geometry>
        <mesh filename="package://staubli/meshes/rx60l/visual/rx60bl_hb6.dae" scale="0.001 0.001 0.001"/>
      </geometry>
      <material name="Gray">
        <color rgba="100 100 100 1.0"/>
      </material>
    </collision>
  </link>
  <link name="staubli_rx60l_tool0"/>
  <joint name="joint_1" type="revolute">
    <origin xyz="0 0 0"/>
    <parent link="staubli_rx60l_link1"/>
    <child link="staubli_rx60l_link2"/>
    <axis xyz="0 0 1"/>
    <limit effort="100" lower="-2.792526803" upper="2.792526803" velocity="5.009094953"/>
  </joint>
  <joint name="joint_2" type="revolute">
    <origin xyz="0 0 0.341"/>
    <parent link="staubli_rx60l_link2"/>
    <child link="staubli_rx60l_link3"/>
    <axis xyz="0 1 0"/>
    <limit effort="100" lower="-2.225294796" upper="2.225294796" velocity="5.009094953"/>
  </joint>
  <joint name="joint_3" type="revolute">
    <origin xyz="0 0.049 0.400"/>
    <parent link="staubli_rx60l_link3"/>
    <child link="staubli_rx60l_link4"/>
    <axis xyz="0 1 0"/>
    <limit effort="100" lower="-2.347467844" upper="2.347467844" velocity="5.567600314"/>
  </joint>
  <joint name="joint_4" type="revolute">
    <origin xyz="0 0 0"/>
    <parent link="staubli_rx60l_link4"/>
    <child link="staubli_rx60l_link5"/>
    <axis xyz="0 0 1"/>
    <limit effort="100" lower="-4.71238898" upper="4.71238898" velocity="7.155849933"/>
  </joint>
  <joint name="joint_5" type="revolute">
    <origin xyz="0 0 0.400"/>
    <parent link="staubli_rx60l_link5"/>
    <child link="staubli_rx60l_link6"/>
    <axis xyz="0 1 0"/>
    <limit effort="100" lower="-1.911135531" upper="2.103121749" velocity="5.585053606"/>
  </joint>
  <joint name="joint_6" type="revolute">
    <origin xyz="0 0 0.065"/>
    <parent link="staubli_rx60l_link6"/>
    <child link="staubli_rx60l_link7"/>
    <axis xyz="0 0 1"/>
    <limit effort="100" lower="-4.71238898" upper="4.71238898" velocity="12.217304764"/>
  </joint>
  <joint name="joint_6-tool0" type="fixed">
    <parent link="staubli_rx60l_link7"/>
    <child link="staubli_rx60l_tool0"/>
    <origin rpy="0 0 0" xyz="0 0 0"/>
  </joint>
  <joint name="left_gripper_joint" type="revolute">
    <axis xyz="0 0 1"/>
    <limit effort="1000.0" lower="0.0" upper="0.548" velocity="0.5"/>
    <origin rpy="0 -1.570796327 0" xyz="0 0.01 0.008"/>
    <parent link="staubli_rx60l_link7"/>
    <child link="left_gripper"/>
  </joint>
  <link name="left_gripper">
    <visual>
      <origin rpy="0.0 0 0" xyz="0 0 0"/>
      <geometry>
        <mesh filename="package://pr2_description/meshes/gripper_v0/l_finger.dae"/>
      </geometry>
    </visual>
  </link>
  <joint name="left_tip_joint" type="fixed">
    <parent link="left_gripper"/>
    <child link="left_tip"/>
  </joint>
  <link name="left_tip">
    <visual>
      <origin rpy="0.0 0 0" xyz="0.09137 0.00495 0"/>
      <geometry>
        <mesh filename="package://pr2_description/meshes/gripper_v0/l_finger_tip.dae"/>
      </geometry>
    </visual>
  </link>
  <joint name="right_gripper_joint" type="revolute">
    <axis xyz="0 0 -1"/>
    <limit effort="1000.0" lower="0.0" upper="0.548" velocity="0.5"/>
    <origin rpy="0 -1.570796327 0" xyz="0 -0.01 0.008"/>
    <parent link="staubli_rx60l_link7"/>
    <child link="right_gripper"/>
  </joint>
  <link name="right_gripper">
    <visual>
      <origin rpy="-3.1415 0 0" xyz="0 0 0"/>
      <geometry>
        <mesh filename="package://pr2_description/meshes/gripper_v0/l_finger.dae"/>
      </geometry>
    </visual>
  </link>
  <joint name="right_tip_joint" type="fixed">
    <parent link="right_gripper"/>
    <child link="right_tip"/>
  </joint>
  <link name="right_tip">
    <visual>
      <origin rpy="-3.1415 0 0" xyz="0.09137 0.00495 0"/>
      <geometry>
        <mesh filename="package://pr2_description/meshes/gripper_v0/l_finger_tip.dae"/>
      </geometry>
    </visual>
  </link>
</robot>
