<robot name="STAUBLI_RX60L">
	<link name="Staubli_RX60L_Link1">
		<visual>
			<origin xyz="0 0 0" rpy="0 0 0"/>
			<geometry>
				<mesh filename="package://staubli/meshes/rx60l/visual/RX60BL_HB.dae" scale="0.001 0.001 0.001"/>
			</geometry>
			<material name="Yellow">
				<color rgba="245 196 0 1.0"/>
			</material>
		</visual>
		<collision>
			<origin xyz="0 0 0" rpy="0 0 0"/>
			<geometry>
				<mesh filename="package://staubli/meshes/rx60l/visual/RX60BL_HB.dae" scale="0.001 0.001 0.001"/>
			</geometry>
			<material name="Blue">
				<color rgba="0 0 255 1.0"/>
			</material>
		</collision>
	</link>
	<link name="Staubli_RX60L_Link2">
		<visual>
			<origin xyz="0 0 0" rpy="0 0 0"/>
			<geometry>
				<mesh filename="package://staubli/meshes/rx60l/visual/RX60BL_HB1.dae" scale="0.001 0.001 0.001"/>
			</geometry>
			<material name="Yellow">
				<color rgba="245 196 0 1.0"/>
			</material>
		</visual>
		<collision>
			<origin xyz="0 0 0" rpy="0 0 0"/>
			<geometry>
				<mesh filename="package://staubli/meshes/rx60l/visual/RX60BL_HB1.dae" scale="0.001 0.001 0.001"/>
			</geometry>
			<material name="Green">
				<color rgba="0 0 255 1.0"/>
			</material>
		</collision>
	</link>	
	<link name="Staubli_RX60L_Link3">
		<visual>
			<origin xyz="0 0 0" rpy="0 0 0"/>
			<geometry>
				<mesh filename="package://staubli/meshes/rx60l/visual/RX60BL_HB2.stl" scale="0.001 0.001 0.001"/>
			</geometry>
			<material name="White">
				<color rgba="0 0 255 1.0"/>
			</material>
		</visual>
		<collision>
			<origin xyz="0 0 0" rpy="0 0 0"/>
			<geometry>
				<mesh filename="package://staubli/meshes/rx60l/visual/RX60BL_HB2.stl" scale="0.001 0.001 0.001"/>
			</geometry>
			<material name="Blue">
				<color rgba="0 0 255 1.0"/>
			</material>
		</collision>
	</link>
	<link name="Staubli_RX60L_Link4">
		<visual>
			<origin xyz="0 0 0" rpy="0 0 0"/>
			<geometry>
				<mesh filename="package://staubli/meshes/rx60l/visual/RX60BL_HB3.dae" scale="0.001 0.001 0.001"/>
			</geometry>
			<material name="Red">
				<color rgba="0 0 255 1.0"/>
			</material>
		</visual>
		<collision>
			<origin xyz="0 0 0" rpy="0 0 0"/>
			<geometry>
				<mesh filename="package://staubli/meshes/rx60l/visual/RX60BL_HB3.dae" scale="0.001 0.001 0.001"/>
			</geometry>
			<material name="Blue">
				<color rgba="0 0 255 1.0"/>
			</material>
		</collision>
	</link>
	<link name="Staubli_RX60L_Link5">
		<visual>
			<origin xyz="0 0 0" rpy="0 0 0"/>
			<geometry>
				<mesh filename="package://staubli/meshes/rx60l/visual/RX60BL_HB4.dae" scale="0.001 0.001 0.001"/>
			</geometry>
			<material name="Blue">
				<color rgba="0 0 255 1.0"/>
			</material>
		</visual>
		<collision>
			<origin xyz="0 0 0" rpy="0 0 0"/>
			<geometry>
				<mesh filename="package://staubli/meshes/rx60l/visual/RX60BL_HB4.dae" scale="0.001 0.001 0.001"/>
			</geometry>
			<material name="Blue">
				<color rgba="0 0 255 1.0"/>
			</material>
		</collision>
	</link>
	<link name="Staubli_RX60L_Link6">
		<visual>
			<origin xyz="0 0 0" rpy="0 0 0"/>
			<geometry>
				<mesh filename="package://staubli/meshes/rx60l/visual/RX60BL_HB5.dae" scale="0.001 0.001 0.001"/>
			</geometry>
			<material name="Blue">
				<color rgba="0 0 255 1.0"/>
			</material>
		</visual>
		<collision>
			<origin xyz="0 0 0" rpy="0 0 0"/>
			<geometry>
				<mesh filename="package://staubli/meshes/rx60l/visual/RX60BL_HB5.dae" scale="0.001 0.001 0.001"/>
			</geometry>
			<material name="Blue">
				<color rgba="0 0 255 1.0"/>
			</material>
		</collision>
	</link>
	
	<link name="Staubli_RX60L_Link7">
		<visual>
			<origin xyz="0 0 0" rpy="0 0 0"/>
			<geometry>
				<mesh filename="package://staubli/meshes/rx60l/visual/RX60BL_HB6.dae" scale="0.001 0.001 0.001"/>
			</geometry>
			<material name="Gray">
				<color rgba="100 100 100 1.0"/>
			</material>
		</visual>
		<collision>
			<origin xyz="0 0 0" rpy="0 0 0"/>
			<geometry>
				<mesh filename="package://staubli/meshes/rx60l/visual/RX60BL_HB6.dae" scale="0.001 0.001 0.001"/>
			</geometry>
			<material name="Gray">
				<color rgba="100 100 100 1.0"/>
			</material>
		</collision>
	</link>
	<joint name="joint_1" type="revolute">
		<origin xyz="0 0 0"/>
		<parent link="Staubli_RX60L_Link1"/>
		<child link="Staubli_RX60L_Link2"/>
		<axis xyz="0 0 1"/>
		<limit effort="100" velocity="5.009094953" lower="-2.792526803" upper="2.792526803"/>
	</joint>
	<joint name="joint_2" type="revolute">
		<origin xyz="0 0 0.341"/>
		<parent link="Staubli_RX60L_Link2"/>
		<child link="Staubli_RX60L_Link3"/>
		<axis xyz="0 1 0"/>
		<limit effort="100" velocity="5.009094953" lower="-2.225294796" upper="2.225294796"/>
	</joint>
	<joint name="joint_3" type="revolute">
		<origin xyz="0 0.049 0.400"/>
		<parent link="Staubli_RX60L_Link3"/>
		<child link="Staubli_RX60L_Link4"/>
		<axis xyz="0 1 0"/>
		<limit effort="100" velocity="5.567600314" lower="-2.347467844" upper="2.347467844"/>
	</joint>
	<joint name="joint_4" type="revolute">
		<origin xyz="0 0 0"/>
		<parent link="Staubli_RX60L_Link4"/>
		<child link="Staubli_RX60L_Link5"/>
		<axis xyz="0 0 1"/>
		<limit effort="100" velocity="7.155849933" lower="-4.71238898" upper="4.71238898"/>
	</joint>
	<joint name="joint_5" type="revolute">
		<origin xyz="0 0 0.400"/>
		<parent link="Staubli_RX60L_Link5"/>
		<child link="Staubli_RX60L_Link6"/>
		<axis xyz="0 1 0"/>
		<limit effort="100" velocity="5.585053606" lower="-1.911135531" upper="2.103121749"/>
	</joint>	
	<joint name="joint_6" type="revolute">
		<origin xyz="0 0 0.065"/>
		<parent link="Staubli_RX60L_Link6"/>
		<child link="Staubli_RX60L_Link7"/>
		<axis xyz="0 0 1"/>
		<limit effort="100" velocity="12.217304764" lower="-4.71238898" upper="4.71238898"/>
	</joint>
	
	<!-- Gripper description beyond this point -->
  <joint name="left_gripper_joint" type="revolute">
    <axis xyz="0 0 1"/>
    <limit effort="1000.0" lower="0.0" upper="0.548" velocity="0.5"/>
    <origin rpy="0 -1.570796327 0" xyz="0 0.01 0.008"/>
    <parent link="Staubli_RX60L_Link7"/>
    <child link="left_gripper"/>
  </joint>

  <link name="left_gripper">
    <visual>
      <origin rpy="0.0 0 0" xyz="0 0 0"/>
      <geometry>
        <mesh filename="package://pr2_description/meshes/gripper_v0/l_finger.dae"/>
      </geometry>
    </visual>
  </link>

  <joint name="left_tip_joint" type="fixed">
    <parent link="left_gripper"/>
    <child link="left_tip"/>
  </joint>

  <link name="left_tip">
    <visual>
      <origin rpy="0.0 0 0" xyz="0.09137 0.00495 0"/>
      <geometry>
        <mesh filename="package://pr2_description/meshes/gripper_v0/l_finger_tip.dae"/>
      </geometry>
    </visual>
  </link>

  <joint name="right_gripper_joint" type="revolute">
    <axis xyz="0 0 -1"/>
    <limit effort="1000.0" lower="0.0" upper="0.548" velocity="0.5"/>
    <origin rpy="0 -1.570796327 0" xyz="0 -0.01 0.008"/>
    <parent link="Staubli_RX60L_Link7"/>
    <child link="right_gripper"/>
  </joint>

  <link name="right_gripper">
    <visual>
      <origin rpy="-3.1415 0 0" xyz="0 0 0"/>
      <geometry>
        <mesh filename="package://pr2_description/meshes/gripper_v0/l_finger.dae"/>
      </geometry>
    </visual>
  </link>

  <joint name="right_tip_joint" type="fixed">
    <parent link="right_gripper"/>
    <child link="right_tip"/>
  </joint>

  <link name="right_tip">
    <visual>
      <origin rpy="-3.1415 0 0" xyz="0.09137 0.00495 0"/>
      <geometry>
        <mesh filename="package://pr2_description/meshes/gripper_v0/l_finger_tip.dae"/>
      </geometry>
    </visual>
  </link>
	
</robot>
